Workbook
Name Avg_Sale_Price: 'Single Project Assumptions'!$L$37
Name Base_Dates_120: Calc_Helper!$C$3:$DR$3
Name Closing_Selected_120: Calc_Helper!$C$73:$DR$73
Name Deposit_Per_Unit: 'Single Project Assumptions'!$L$42
Name DevCF_All_120: Calc_Helper!$C$57:$DR$57
Name DevCF_All_Neg_120: Calc_Helper!$C$56:$DR$56
Name DevCF_All_Pos_120: Calc_Helper!$C$55:$DR$55
Name DevCF_P1_120: Calc_Helper!$C$58:$DR$58
Name DevCF_P2Plus_120: Calc_Helper!$C$59:$DR$59
Name DevCF_Selected_120: Calc_Helper!$C$72:$DR$72
Name Model_StartDate: 'Single Project Assumptions'!$D$6
Name Sales_BrokerSelected_120: Calc_Helper!$C$74:$DR$74
Name Sales_Selected_120: Calc_Helper!$C$70:$DR$70
Name Units_Per_Project: 'Single Project Assumptions'!$D$21

Sheet Title Page
M8: EP PROJECT
M9: Platform Model | N9: Version 1
M10: Author | N10: Tom
M11: Production Date | N11: 46012
M14: Lets go back to the future and create lives people can afford to live
M16: Your future is whatever you make it. So make it a good one.
M18: -Doc Brown - Back to the Future Part III
B40: A capital-light coordination platform for building intentional communities

Sheet Dashboard
C3: THE COMMONS DASHBOARD
C5: The Commons Key Metrics (Portfolio View) | L5: Risk-Adjusted Investor Returns | U5: Single Project Key Metrics | AM5: Day 1 Yield | AN5: ='Single Project Assumptions'!D49 -> 0.02
C6: Number of Projects | E6: Successful Entitlements | G6: 10 Year Platform Revenue | I6: 10 Year EBITDA | U6: Number of Units | W6: Total Development Cost | Y6: Gross Development Value | AA6: Profit on Cost | AM6: Stabilized Yield | AN6: ='Single Project Assumptions'!D51 -> 0.15
C7: =MAX('Platform Assumptions'!B6:B15) -> 10 | E7: =COUNTIF('Platform Assumptions'!E6:E15,"Yes") -> 5 | G7: ='The Commons Platform CF'!D17/1000000 -> 17.33076 | I7: ='The Commons Platform CF'!D21/1000000 -> 12.289093 | U7: ='Single Project Assumptions'!D21 -> 150 | W7: ='Single Project Assumptions'!L31/1000000 -> 159.525 | Y7: ='Single Project Assumptions'!L38/1000000 -> 225 | AA7: =(Y7-W7)/W7 -> 0.41043724
AM8: Entitlement Investor IRR | AN8: ='Entitlement Phase'!D13 -> 0.41443852
AM9: Development Investor IRR | AN9: ='Development Phase'!D29 -> 0.22888162
C10: Day 1 Landowner Economics | U10: Sale Assumptions
C11: Day 1 Land Value | E11: Farming Yield | G11: Farming Income | I11: Farming Risk | U11: Sale Period | W11: Velocity Units / Month | Y11: Deposit Assumed | AA11: Paid On Completion | AM11: Land Stewardship Fee (Landowner) | AP11: ='Single Project Assumptions'!D53 -> 1000
C12: ='Single Project Assumptions'!D48/1000000 -> 1 | E12: ='Single Project Assumptions'!D49 -> 0.02 | G12: ='Single Project Assumptions'!D50/1000000 -> 0.02 | I12: High | U12: ='Single Project Assumptions'!P13 -> 18 | W12: ='Single Project Assumptions'!P15 -> 8.3333333 | Y12: ='Single Project Assumptions'!L41 -> 0.15 | AA12: =1-Y12 -> 0.85 | AM12: Operations Fee (Commons) | AP12: ='Single Project Assumptions'!P50 -> 1800
AM13: Service Charges (Community) | AP13: ='Single Project Assumptions'!T50 -> 2400
C14: Very poor day 1 economics with high farming risks and potential for negative yields | AM14: Total Fees | AP14: =SUM(AP11:AP13) -> 5200
C18: Stabilized Landowner Economics (The Commons Targets) | L18: Total Annual Fees Paid By End Residents | U18: KEY MODEL EXCLUSIONS TO NOTE
C19: Day 1 Land Value | E19: Target Yield | G19: Stewardship Income | I19: Operational Risk | U19: It is important to note that this is a v1 model that makes several key exclusions in the spriit of simplicity. Additional functionality can be added in at a later stage as required.
C20: =C12 -> 1 | E20: ='Single Project Assumptions'!D51 -> 0.15 | G20: ='Single Project Assumptions'!D52/1000000 -> 0.15 | I20: Low
U21: External Debt Financing | Y21: Growth and Inflation
U23: Development Phasing | Y23: Detailed Development Budgets
U25: Taxes | Y25: Developer Incentives (e.g. Carried Interest)
U28: The Commons is a capital-light coordination platform that aligns landowners, entitlement capital, developers, and residents through repeatable project structures.

Sheet Platform Cash Flow--->
M4: Description
M5: This section rolls up multiple Commons projects into a single platform-level cash flow. Some projects succeed, some fail — that’s the point. By toggling entitlement outcomes on and off, we can see how The Commons performs as a portfolio rather than a one-off development bet. Central overhead is included to reflect the reality of running the platform.

Sheet Platform Assumptions
B3: PLATFORM ASSUMPTIONS
B5: Project Number | C5: Months Lag | D5: Start Date | E5: Entitlement Success | G5: Central Overhead Costs
B6: 1 | D6: ='Single Project Assumptions'!D6 -> 46387 | E6: Yes | G6: Costs / Year | I6: 500000
B7: =B6+1 -> 2 | C7: 3 | D7: =EOMONTH(D6,C7) -> 46477 | E7: No | G7: Costs / Month | I7: =I6/12 -> 41666.667
B8: =B7+1 -> 3 | C8: =C7 -> 3 | D8: =EOMONTH(D7,C8) -> 46568 | E8: Yes
B9: =B8+1 -> 4 | C9: =C8 -> 3 | D9: =EOMONTH(D8,C9) -> 46660 | E9: No
B10: =B9+1 -> 5 | C10: =C9 -> 3 | D10: =EOMONTH(D9,C10) -> 46752 | E10: Yes
B11: =B10+1 -> 6 | C11: =C10 -> 3 | D11: =EOMONTH(D10,C11) -> 46843 | E11: No
B12: =B11+1 -> 7 | C12: =C11 -> 3 | D12: =EOMONTH(D11,C12) -> 46934 | E12: Yes
B13: =B12+1 -> 8 | C13: =C12 -> 3 | D13: =EOMONTH(D12,C13) -> 47026 | E13: No
B14: =B13+1 -> 9 | C14: =C13 -> 3 | D14: =EOMONTH(D13,C14) -> 47118 | E14: Yes
B15: =B14+1 -> 10 | C15: =C14 -> 3 | D15: =EOMONTH(D14,C15) -> 47208 | E15: No
B19: PROJECT STAGGERED CASH FLOWS
B21: Project Cash Flows
B22: Project 1 | C22: Total | D22: =D6 -> 46387 | E22: =EOMONTH(D22,1) -> 46418 | F22: =EOMONTH(E22,1) -> 46446 | G22: =EOMONTH(F22,1) -> 46477 | H22: =EOMONTH(G22,1) -> 46507 | I22: =EOMONTH(H22,1) -> 46538 | J22: =EOMONTH(I22,1) -> 46568 | K22: =EOMONTH(J22,1) -> 46599 | L22: =EOMONTH(K22,1) -> 46630 | ... DT22: =EOMONTH(DS22,1) -> 50040
B23: Cash Flow | C23: =SUM(D23:DT23) -> 3393552 | D23: =IF($E$6="Yes",'Rolled Up Cash Flows'!E$31,'Rolled Up Cash Flows'!E$53) -> 46666.667 | E23: =IF($E$6="Yes",'Rolled Up Cash Flows'!F$31,'Rolled Up Cash Flows'!F$53) -> -3333.3333 | F23: =IF($E$6="Yes",'Rolled Up Cash Flows'!G$31,'Rolled Up Cash Flows'!G$53) -> -3333.3333 | G23: =IF($E$6="Yes",'Rolled Up Cash Flows'!H$31,'Rolled Up Cash Flows'!H$53) -> -3333.3333 | H23: =IF($E$6="Yes",'Rolled Up Cash Flows'!I$31,'Rolled Up Cash Flows'!I$53) -> -3333.3333 | I23: =IF($E$6="Yes",'Rolled Up Cash Flows'!J$31,'Rolled Up Cash Flows'!J$53) -> -3333.3333 | J23: =IF($E$6="Yes",'Rolled Up Cash Flows'!K$31,'Rolled Up Cash Flows'!K$53) -> 6250 | K23: =IF($E$6="Yes",'Rolled Up Cash Flows'!L$31,'Rolled Up Cash Flows'!L$53) -> 6250 | ... DT23: =IF($E$6="Yes",'Rolled Up Cash Flows'!DU$31,'Rolled Up Cash Flows'!DU$53) -> 0
B25: Project 2 | C25: Total | D25: =D7 -> 46477 | E25: =EOMONTH(D25,1) -> 46507 | F25: =EOMONTH(E25,1) -> 46538 | G25: =EOMONTH(F25,1) -> 46568 | H25: =EOMONTH(G25,1) -> 46599 | I25: =EOMONTH(H25,1) -> 46630 | J25: =EOMONTH(I25,1) -> 46660 | K25: =EOMONTH(J25,1) -> 46691 | L25: =EOMONTH(K25,1) -> 46721 | ... DT25: =EOMONTH(DS25,1) -> 50130
B26: Cash Flow | C26: =SUM(D26:DT26) -> 105000 | D26: =IF($E$7="Yes",'Rolled Up Cash Flows'!E$31,'Rolled Up Cash Flows'!E$53) -> 46666.667 | E26: =IF($E$7="Yes",'Rolled Up Cash Flows'!F$31,'Rolled Up Cash Flows'!F$53) -> -3333.3333 | F26: =IF($E$7="Yes",'Rolled Up Cash Flows'!G$31,'Rolled Up Cash Flows'!G$53) -> -3333.3333 | G26: =IF($E$7="Yes",'Rolled Up Cash Flows'!H$31,'Rolled Up Cash Flows'!H$53) -> -3333.3333 | H26: =IF($E$7="Yes",'Rolled Up Cash Flows'!I$31,'Rolled Up Cash Flows'!I$53) -> -3333.3333 | I26: =IF($E$7="Yes",'Rolled Up Cash Flows'!J$31,'Rolled Up Cash Flows'!J$53) -> -3333.3333 | J26: =IF($E$7="Yes",'Rolled Up Cash Flows'!K$31,'Rolled Up Cash Flows'!K$53) -> 6250 | K26: =IF($E$7="Yes",'Rolled Up Cash Flows'!L$31,'Rolled Up Cash Flows'!L$53) -> 6250 | ... DT26: =IF($E$7="Yes",'Rolled Up Cash Flows'!DU$31,'Rolled Up Cash Flows'!DU$53) -> 0
B28: Project 3 | C28: Total | D28: =D8 -> 46568 | E28: =EOMONTH(D28,1) -> 46599 | F28: =EOMONTH(E28,1) -> 46630 | G28: =EOMONTH(F28,1) -> 46660 | H28: =EOMONTH(G28,1) -> 46691 | I28: =EOMONTH(H28,1) -> 46721 | J28: =EOMONTH(I28,1) -> 46752 | K28: =EOMONTH(J28,1) -> 46783 | L28: =EOMONTH(K28,1) -> 46812 | ... DT28: =EOMONTH(DS28,1) -> 50221
B29: Cash Flow | C29: =SUM(D29:DT29) -> 3393552 | D29: =IF($E$8="Yes",'Rolled Up Cash Flows'!E$31,'Rolled Up Cash Flows'!E$53) -> 46666.667 | E29: =IF($E$8="Yes",'Rolled Up Cash Flows'!F$31,'Rolled Up Cash Flows'!F$53) -> -3333.3333 | F29: =IF($E$8="Yes",'Rolled Up Cash Flows'!G$31,'Rolled Up Cash Flows'!G$53) -> -3333.3333 | G29: =IF($E$8="Yes",'Rolled Up Cash Flows'!H$31,'Rolled Up Cash Flows'!H$53) -> -3333.3333 | H29: =IF($E$8="Yes",'Rolled Up Cash Flows'!I$31,'Rolled Up Cash Flows'!I$53) -> -3333.3333 | I29: =IF($E$8="Yes",'Rolled Up Cash Flows'!J$31,'Rolled Up Cash Flows'!J$53) -> -3333.3333 | J29: =IF($E$8="Yes",'Rolled Up Cash Flows'!K$31,'Rolled Up Cash Flows'!K$53) -> 6250 | K29: =IF($E$8="Yes",'Rolled Up Cash Flows'!L$31,'Rolled Up Cash Flows'!L$53) -> 6250 | ... DT29: =IF($E$8="Yes",'Rolled Up Cash Flows'!DU$31,'Rolled Up Cash Flows'!DU$53) -> 0
B31: Project 4 | C31: Total | D31: =D9 -> 46660 | E31: =EOMONTH(D31,1) -> 46691 | F31: =EOMONTH(E31,1) -> 46721 | G31: =EOMONTH(F31,1) -> 46752 | H31: =EOMONTH(G31,1) -> 46783 | I31: =EOMONTH(H31,1) -> 46812 | J31: =EOMONTH(I31,1) -> 46843 | K31: =EOMONTH(J31,1) -> 46873 | L31: =EOMONTH(K31,1) -> 46904 | ... DT31: =EOMONTH(DS31,1) -> 50313
B32: Cash Flow | C32: =SUM(D32:DT32) -> 105000 | D32: =IF($E$9="Yes",'Rolled Up Cash Flows'!E$31,'Rolled Up Cash Flows'!E$53) -> 46666.667 | E32: =IF($E$9="Yes",'Rolled Up Cash Flows'!F$31,'Rolled Up Cash Flows'!F$53) -> -3333.3333 | F32: =IF($E$9="Yes",'Rolled Up Cash Flows'!G$31,'Rolled Up Cash Flows'!G$53) -> -3333.3333 | G32: =IF($E$9="Yes",'Rolled Up Cash Flows'!H$31,'Rolled Up Cash Flows'!H$53) -> -3333.3333 | H32: =IF($E$9="Yes",'Rolled Up Cash Flows'!I$31,'Rolled Up Cash Flows'!I$53) -> -3333.3333 | I32: =IF($E$9="Yes",'Rolled Up Cash Flows'!J$31,'Rolled Up Cash Flows'!J$53) -> -3333.3333 | J32: =IF($E$9="Yes",'Rolled Up Cash Flows'!K$31,'Rolled Up Cash Flows'!K$53) -> 6250 | K32: =IF($E$9="Yes",'Rolled Up Cash Flows'!L$31,'Rolled Up Cash Flows'!L$53) -> 6250 | ... DT32: =IF($E$9="Yes",'Rolled Up Cash Flows'!DU$31,'Rolled Up Cash Flows'!DU$53) -> 0
B34: Project 5 | C34: Total | D34: =D10 -> 46752 | E34: =EOMONTH(D34,1) -> 46783 | F34: =EOMONTH(E34,1) -> 46812 | G34: =EOMONTH(F34,1) -> 46843 | H34: =EOMONTH(G34,1) -> 46873 | I34: =EOMONTH(H34,1) -> 46904 | J34: =EOMONTH(I34,1) -> 46934 | K34: =EOMONTH(J34,1) -> 46965 | L34: =EOMONTH(K34,1) -> 46996 | ... DT34: =EOMONTH(DS34,1) -> 50405
B35: Cash Flow | C35: =SUM(D35:DT35) -> 3393552 | D35: =IF($E$10="Yes",'Rolled Up Cash Flows'!E$31,'Rolled Up Cash Flows'!E$53) -> 46666.667 | E35: =IF($E$10="Yes",'Rolled Up Cash Flows'!F$31,'Rolled Up Cash Flows'!F$53) -> -3333.3333 | F35: =IF($E$10="Yes",'Rolled Up Cash Flows'!G$31,'Rolled Up Cash Flows'!G$53) -> -3333.3333 | G35: =IF($E$10="Yes",'Rolled Up Cash Flows'!H$31,'Rolled Up Cash Flows'!H$53) -> -3333.3333 | H35: =IF($E$10="Yes",'Rolled Up Cash Flows'!I$31,'Rolled Up Cash Flows'!I$53) -> -3333.3333 | I35: =IF($E$10="Yes",'Rolled Up Cash Flows'!J$31,'Rolled Up Cash Flows'!J$53) -> -3333.3333 | J35: =IF($E$10="Yes",'Rolled Up Cash Flows'!K$31,'Rolled Up Cash Flows'!K$53) -> 6250 | K35: =IF($E$10="Yes",'Rolled Up Cash Flows'!L$31,'Rolled Up Cash Flows'!L$53) -> 6250 | ... DT35: =IF($E$10="Yes",'Rolled Up Cash Flows'!DU$31,'Rolled Up Cash Flows'!DU$53) -> 0
B37: Project 6 | C37: Total | D37: =D11 -> 46843 | E37: =EOMONTH(D37,1) -> 46873 | F37: =EOMONTH(E37,1) -> 46904 | G37: =EOMONTH(F37,1) -> 46934 | H37: =EOMONTH(G37,1) -> 46965 | I37: =EOMONTH(H37,1) -> 46996 | J37: =EOMONTH(I37,1) -> 47026 | K37: =EOMONTH(J37,1) -> 47057 | L37: =EOMONTH(K37,1) -> 47087 | ... DT37: =EOMONTH(DS37,1) -> 50495
B38: Cash Flow | C38: =SUM(D38:DT38) -> 105000 | D38: =IF($E$11="Yes",'Rolled Up Cash Flows'!E$31,'Rolled Up Cash Flows'!E$53) -> 46666.667 | E38: =IF($E$11="Yes",'Rolled Up Cash Flows'!F$31,'Rolled Up Cash Flows'!F$53) -> -3333.3333 | F38: =IF($E$11="Yes",'Rolled Up Cash Flows'!G$31,'Rolled Up Cash Flows'!G$53) -> -3333.3333 | G38: =IF($E$11="Yes",'Rolled Up Cash Flows'!H$31,'Rolled Up Cash Flows'!H$53) -> -3333.3333 | H38: =IF($E$11="Yes",'Rolled Up Cash Flows'!I$31,'Rolled Up Cash Flows'!I$53) -> -3333.3333 | I38: =IF($E$11="Yes",'Rolled Up Cash Flows'!J$31,'Rolled Up Cash Flows'!J$53) -> -3333.3333 | J38: =IF($E$11="Yes",'Rolled Up Cash Flows'!K$31,'Rolled Up Cash Flows'!K$53) -> 6250 | K38: =IF($E$11="Yes",'Rolled Up Cash Flows'!L$31,'Rolled Up Cash Flows'!L$53) -> 6250 | ... DT38: =IF($E$11="Yes",'Rolled Up Cash Flows'!DU$31,'Rolled Up Cash Flows'!DU$53) -> 0
B40: Project 7 | C40: Total | D40: =D12 -> 46934 | E40: =EOMONTH(D40,1) -> 46965 | F40: =EOMONTH(E40,1) -> 46996 | G40: =EOMONTH(F40,1) -> 47026 | H40: =EOMONTH(G40,1) -> 47057 | I40: =EOMONTH(H40,1) -> 47087 | J40: =EOMONTH(I40,1) -> 47118 | K40: =EOMONTH(J40,1) -> 47149 | L40: =EOMONTH(K40,1) -> 47177 | ... DT40: =EOMONTH(DS40,1) -> 50586
B41: Cash Flow | C41: =SUM(D41:DT41) -> 3393552 | D41: =IF($E$12="Yes",'Rolled Up Cash Flows'!E$31,'Rolled Up Cash Flows'!E$53) -> 46666.667 | E41: =IF($E$12="Yes",'Rolled Up Cash Flows'!F$31,'Rolled Up Cash Flows'!F$53) -> -3333.3333 | F41: =IF($E$12="Yes",'Rolled Up Cash Flows'!G$31,'Rolled Up Cash Flows'!G$53) -> -3333.3333 | G41: =IF($E$12="Yes",'Rolled Up Cash Flows'!H$31,'Rolled Up Cash Flows'!H$53) -> -3333.3333 | H41: =IF($E$12="Yes",'Rolled Up Cash Flows'!I$31,'Rolled Up Cash Flows'!I$53) -> -3333.3333 | I41: =IF($E$12="Yes",'Rolled Up Cash Flows'!J$31,'Rolled Up Cash Flows'!J$53) -> -3333.3333 | J41: =IF($E$12="Yes",'Rolled Up Cash Flows'!K$31,'Rolled Up Cash Flows'!K$53) -> 6250 | K41: =IF($E$12="Yes",'Rolled Up Cash Flows'!L$31,'Rolled Up Cash Flows'!L$53) -> 6250 | ... DT41: =IF($E$12="Yes",'Rolled Up Cash Flows'!DU$31,'Rolled Up Cash Flows'!DU$53) -> 0
B43: Project 8 | C43: Total | D43: =D13 -> 47026 | E43: =EOMONTH(D43,1) -> 47057 | F43: =EOMONTH(E43,1) -> 47087 | G43: =EOMONTH(F43,1) -> 47118 | H43: =EOMONTH(G43,1) -> 47149 | I43: =EOMONTH(H43,1) -> 47177 | J43: =EOMONTH(I43,1) -> 47208 | K43: =EOMONTH(J43,1) -> 47238 | L43: =EOMONTH(K43,1) -> 47269 | ... DT43: =EOMONTH(DS43,1) -> 50678
B44: Cash Flow | C44: =SUM(D44:DT44) -> 105000 | D44: =IF($E$13="Yes",'Rolled Up Cash Flows'!E$31,'Rolled Up Cash Flows'!E$53) -> 46666.667 | E44: =IF($E$13="Yes",'Rolled Up Cash Flows'!F$31,'Rolled Up Cash Flows'!F$53) -> -3333.3333 | F44: =IF($E$13="Yes",'Rolled Up Cash Flows'!G$31,'Rolled Up Cash Flows'!G$53) -> -3333.3333 | G44: =IF($E$13="Yes",'Rolled Up Cash Flows'!H$31,'Rolled Up Cash Flows'!H$53) -> -3333.3333 | H44: =IF($E$13="Yes",'Rolled Up Cash Flows'!I$31,'Rolled Up Cash Flows'!I$53) -> -3333.3333 | I44: =IF($E$13="Yes",'Rolled Up Cash Flows'!J$31,'Rolled Up Cash Flows'!J$53) -> -3333.3333 | J44: =IF($E$13="Yes",'Rolled Up Cash Flows'!K$31,'Rolled Up Cash Flows'!K$53) -> 6250 | K44: =IF($E$13="Yes",'Rolled Up Cash Flows'!L$31,'Rolled Up Cash Flows'!L$53) -> 6250 | ... DT44: =IF($E$13="Yes",'Rolled Up Cash Flows'!DU$31,'Rolled Up Cash Flows'!DU$53) -> 0
B46: Project 9 | C46: Total | D46: =D14 -> 47118 | E46: =EOMONTH(D46,1) -> 47149 | F46: =EOMONTH(E46,1) -> 47177 | G46: =EOMONTH(F46,1) -> 47208 | H46: =EOMONTH(G46,1) -> 47238 | I46: =EOMONTH(H46,1) -> 47269 | J46: =EOMONTH(I46,1) -> 47299 | K46: =EOMONTH(J46,1) -> 47330 | L46: =EOMONTH(K46,1) -> 47361 | ... DT46: =EOMONTH(DS46,1) -> 50770
B47: Cash Flow | C47: =SUM(D47:DT47) -> 3393552 | D47: =IF($E$14="Yes",'Rolled Up Cash Flows'!E$31,'Rolled Up Cash Flows'!E$53) -> 46666.667 | E47: =IF($E$14="Yes",'Rolled Up Cash Flows'!F$31,'Rolled Up Cash Flows'!F$53) -> -3333.3333 | F47: =IF($E$14="Yes",'Rolled Up Cash Flows'!G$31,'Rolled Up Cash Flows'!G$53) -> -3333.3333 | G47: =IF($E$14="Yes",'Rolled Up Cash Flows'!H$31,'Rolled Up Cash Flows'!H$53) -> -3333.3333 | H47: =IF($E$14="Yes",'Rolled Up Cash Flows'!I$31,'Rolled Up Cash Flows'!I$53) -> -3333.3333 | I47: =IF($E$14="Yes",'Rolled Up Cash Flows'!J$31,'Rolled Up Cash Flows'!J$53) -> -3333.3333 | J47: =IF($E$14="Yes",'Rolled Up Cash Flows'!K$31,'Rolled Up Cash Flows'!K$53) -> 6250 | K47: =IF($E$14="Yes",'Rolled Up Cash Flows'!L$31,'Rolled Up Cash Flows'!L$53) -> 6250 | ... DT47: =IF($E$14="Yes",'Rolled Up Cash Flows'!DU$31,'Rolled Up Cash Flows'!DU$53) -> 0
B49: Project 10 | C49: Total | D49: =D15 -> 47208 | E49: =EOMONTH(D49,1) -> 47238 | F49: =EOMONTH(E49,1) -> 47269 | G49: =EOMONTH(F49,1) -> 47299 | H49: =EOMONTH(G49,1) -> 47330 | I49: =EOMONTH(H49,1) -> 47361 | J49: =EOMONTH(I49,1) -> 47391 | K49: =EOMONTH(J49,1) -> 47422 | L49: =EOMONTH(K49,1) -> 47452 | ... DT49: =EOMONTH(DS49,1) -> 50860
B50: Cash Flow | C50: =SUM(D50:DT50) -> 105000 | D50: =IF($E$15="Yes",'Rolled Up Cash Flows'!E$31,'Rolled Up Cash Flows'!E$53) -> 46666.667 | E50: =IF($E$15="Yes",'Rolled Up Cash Flows'!F$31,'Rolled Up Cash Flows'!F$53) -> -3333.3333 | F50: =IF($E$15="Yes",'Rolled Up Cash Flows'!G$31,'Rolled Up Cash Flows'!G$53) -> -3333.3333 | G50: =IF($E$15="Yes",'Rolled Up Cash Flows'!H$31,'Rolled Up Cash Flows'!H$53) -> -3333.3333 | H50: =IF($E$15="Yes",'Rolled Up Cash Flows'!I$31,'Rolled Up Cash Flows'!I$53) -> -3333.3333 | I50: =IF($E$15="Yes",'Rolled Up Cash Flows'!J$31,'Rolled Up Cash Flows'!J$53) -> -3333.3333 | J50: =IF($E$15="Yes",'Rolled Up Cash Flows'!K$31,'Rolled Up Cash Flows'!K$53) -> 6250 | K50: =IF($E$15="Yes",'Rolled Up Cash Flows'!L$31,'Rolled Up Cash Flows'!L$53) -> 6250 | ... DT50: =IF($E$15="Yes",'Rolled Up Cash Flows'!DU$31,'Rolled Up Cash Flows'!DU$53) -> 0
A72: Yes
A73: No

Sheet The Commons Platform CF
D3: Year | E3: =YEAR(E4) -> 2026 | F3: =YEAR(F4) -> 2027 | G3: =YEAR(G4) -> 2027 | H3: =YEAR(H4) -> 2027 | I3: =YEAR(I4) -> 2027 | J3: =YEAR(J4) -> 2027 | K3: =YEAR(K4) -> 2027 | L3: =YEAR(L4) -> 2027 | ... DU3: =YEAR(DU4) -> 2036
C4: The Commons Platform Cash Flow | D4: Total | E4: ='Single Project Assumptions'!D11 -> 46387 | F4: =EOMONTH(E4,1) -> 46418 | G4: =EOMONTH(F4,1) -> 46446 | H4: =EOMONTH(G4,1) -> 46477 | I4: =EOMONTH(H4,1) -> 46507 | J4: =EOMONTH(I4,1) -> 46538 | K4: =EOMONTH(J4,1) -> 46568 | L4: =EOMONTH(K4,1) -> 46599 | M4: =EOMONTH(L4,1) -> 46630 | ... DU4: =EOMONTH(DT4,1) -> 50040
C6: Project Level Cash Flows
C7: 1 | D7: =SUM(E7:DU7) -> 3393552 | E7: =IF(E$4<'Platform Assumptions'!$D$22,0,HLOOKUP(E$4,'Platform Assumptions'!$D22:$DT23,2,FALSE)) -> 46666.667 | F7: =IF(F$4<'Platform Assumptions'!$D$22,0,HLOOKUP(F$4,'Platform Assumptions'!$D22:$DT23,2,FALSE)) -> -3333.3333 | G7: =IF(G$4<'Platform Assumptions'!$D$22,0,HLOOKUP(G$4,'Platform Assumptions'!$D22:$DT23,2,FALSE)) -> -3333.3333 | H7: =IF(H$4<'Platform Assumptions'!$D$22,0,HLOOKUP(H$4,'Platform Assumptions'!$D22:$DT23,2,FALSE)) -> -3333.3333 | I7: =IF(I$4<'Platform Assumptions'!$D$22,0,HLOOKUP(I$4,'Platform Assumptions'!$D22:$DT23,2,FALSE)) -> -3333.3333 | J7: =IF(J$4<'Platform Assumptions'!$D$22,0,HLOOKUP(J$4,'Platform Assumptions'!$D22:$DT23,2,FALSE)) -> -3333.3333 | K7: =IF(K$4<'Platform Assumptions'!$D$22,0,HLOOKUP(K$4,'Platform Assumptions'!$D22:$DT23,2,FALSE)) -> 6250 | L7: =IF(L$4<'Platform Assumptions'!$D$22,0,HLOOKUP(L$4,'Platform Assumptions'!$D22:$DT23,2,FALSE)) -> 6250 | ... DU7: =IF(DU$4<'Platform Assumptions'!$D$22,0,HLOOKUP(DU$4,'Platform Assumptions'!$D22:$DT23,2,FALSE)) -> 0
C8: =C7+1 -> 2 | D8: =SUM(E8:DU8) -> 105000 | E8: =IF(E$4<'Platform Assumptions'!$D$25,0,HLOOKUP(E$4,'Platform Assumptions'!$D25:$DT26,2,FALSE)) -> 0 | F8: =IF(F$4<'Platform Assumptions'!$D$25,0,HLOOKUP(F$4,'Platform Assumptions'!$D25:$DT26,2,FALSE)) -> 0 | G8: =IF(G$4<'Platform Assumptions'!$D$25,0,HLOOKUP(G$4,'Platform Assumptions'!$D25:$DT26,2,FALSE)) -> 0 | H8: =IF(H$4<'Platform Assumptions'!$D$25,0,HLOOKUP(H$4,'Platform Assumptions'!$D25:$DT26,2,FALSE)) -> 46666.667 | I8: =IF(I$4<'Platform Assumptions'!$D$25,0,HLOOKUP(I$4,'Platform Assumptions'!$D25:$DT26,2,FALSE)) -> -3333.3333 | J8: =IF(J$4<'Platform Assumptions'!$D$25,0,HLOOKUP(J$4,'Platform Assumptions'!$D25:$DT26,2,FALSE)) -> -3333.3333 | K8: =IF(K$4<'Platform Assumptions'!$D$25,0,HLOOKUP(K$4,'Platform Assumptions'!$D25:$DT26,2,FALSE)) -> -3333.3333 | L8: =IF(L$4<'Platform Assumptions'!$D$25,0,HLOOKUP(L$4,'Platform Assumptions'!$D25:$DT26,2,FALSE)) -> -3333.3333 | ... DU8: =IF(DU$4<'Platform Assumptions'!$D$25,0,HLOOKUP(DU$4,'Platform Assumptions'!$D25:$DT26,2,FALSE)) -> 0
C9: =C8+1 -> 3 | D9: =SUM(E9:DU9) -> 3393552 | E9: =IF(E$4<'Platform Assumptions'!$D$28,0,HLOOKUP(E$4,'Platform Assumptions'!$D28:$DT29,2,FALSE)) -> 0 | F9: =IF(F$4<'Platform Assumptions'!$D$28,0,HLOOKUP(F$4,'Platform Assumptions'!$D28:$DT29,2,FALSE)) -> 0 | G9: =IF(G$4<'Platform Assumptions'!$D$28,0,HLOOKUP(G$4,'Platform Assumptions'!$D28:$DT29,2,FALSE)) -> 0 | H9: =IF(H$4<'Platform Assumptions'!$D$28,0,HLOOKUP(H$4,'Platform Assumptions'!$D28:$DT29,2,FALSE)) -> 0 | I9: =IF(I$4<'Platform Assumptions'!$D$28,0,HLOOKUP(I$4,'Platform Assumptions'!$D28:$DT29,2,FALSE)) -> 0 | J9: =IF(J$4<'Platform Assumptions'!$D$28,0,HLOOKUP(J$4,'Platform Assumptions'!$D28:$DT29,2,FALSE)) -> 0 | K9: =IF(K$4<'Platform Assumptions'!$D$28,0,HLOOKUP(K$4,'Platform Assumptions'!$D28:$DT29,2,FALSE)) -> 46666.667 | L9: =IF(L$4<'Platform Assumptions'!$D$28,0,HLOOKUP(L$4,'Platform Assumptions'!$D28:$DT29,2,FALSE)) -> -3333.3333 | ... DU9: =IF(DU$4<'Platform Assumptions'!$D$28,0,HLOOKUP(DU$4,'Platform Assumptions'!$D28:$DT29,2,FALSE)) -> 0
C10: =C9+1 -> 4 | D10: =SUM(E10:DU10) -> 105000 | E10: =IF(E$4<'Platform Assumptions'!$D$31,0,HLOOKUP(E$4,'Platform Assumptions'!$D31:$DT32,2,FALSE)) -> 0 | F10: =IF(F$4<'Platform Assumptions'!$D$31,0,HLOOKUP(F$4,'Platform Assumptions'!$D31:$DT32,2,FALSE)) -> 0 | G10: =IF(G$4<'Platform Assumptions'!$D$31,0,HLOOKUP(G$4,'Platform Assumptions'!$D31:$DT32,2,FALSE)) -> 0 | H10: =IF(H$4<'Platform Assumptions'!$D$31,0,HLOOKUP(H$4,'Platform Assumptions'!$D31:$DT32,2,FALSE)) -> 0 | I10: =IF(I$4<'Platform Assumptions'!$D$31,0,HLOOKUP(I$4,'Platform Assumptions'!$D31:$DT32,2,FALSE)) -> 0 | J10: =IF(J$4<'Platform Assumptions'!$D$31,0,HLOOKUP(J$4,'Platform Assumptions'!$D31:$DT32,2,FALSE)) -> 0 | K10: =IF(K$4<'Platform Assumptions'!$D$31,0,HLOOKUP(K$4,'Platform Assumptions'!$D31:$DT32,2,FALSE)) -> 0 | L10: =IF(L$4<'Platform Assumptions'!$D$31,0,HLOOKUP(L$4,'Platform Assumptions'!$D31:$DT32,2,FALSE)) -> 0 | ... DU10: =IF(DU$4<'Platform Assumptions'!$D$31,0,HLOOKUP(DU$4,'Platform Assumptions'!$D31:$DT32,2,FALSE)) -> 0
C11: =C10+1 -> 5 | D11: =SUM(E11:DU11) -> 3380052 | E11: =IF(E$4<'Platform Assumptions'!$D$34,0,HLOOKUP(E$4,'Platform Assumptions'!$D34:$DT35,2,FALSE)) -> 0 | F11: =IF(F$4<'Platform Assumptions'!$D$34,0,HLOOKUP(F$4,'Platform Assumptions'!$D34:$DT35,2,FALSE)) -> 0 | G11: =IF(G$4<'Platform Assumptions'!$D$34,0,HLOOKUP(G$4,'Platform Assumptions'!$D34:$DT35,2,FALSE)) -> 0 | H11: =IF(H$4<'Platform Assumptions'!$D$34,0,HLOOKUP(H$4,'Platform Assumptions'!$D34:$DT35,2,FALSE)) -> 0 | I11: =IF(I$4<'Platform Assumptions'!$D$34,0,HLOOKUP(I$4,'Platform Assumptions'!$D34:$DT35,2,FALSE)) -> 0 | J11: =IF(J$4<'Platform Assumptions'!$D$34,0,HLOOKUP(J$4,'Platform Assumptions'!$D34:$DT35,2,FALSE)) -> 0 | K11: =IF(K$4<'Platform Assumptions'!$D$34,0,HLOOKUP(K$4,'Platform Assumptions'!$D34:$DT35,2,FALSE)) -> 0 | L11: =IF(L$4<'Platform Assumptions'!$D$34,0,HLOOKUP(L$4,'Platform Assumptions'!$D34:$DT35,2,FALSE)) -> 0 | ... DU11: =IF(DU$4<'Platform Assumptions'!$D$34,0,HLOOKUP(DU$4,'Platform Assumptions'!$D34:$DT35,2,FALSE)) -> 6750
C12: =C11+1 -> 6 | D12: =SUM(E12:DU12) -> 105000 | E12: =IF(E$4<'Platform Assumptions'!$D$37,0,HLOOKUP(E$4,'Platform Assumptions'!$D37:$DT38,2,FALSE)) -> 0 | F12: =IF(F$4<'Platform Assumptions'!$D$37,0,HLOOKUP(F$4,'Platform Assumptions'!$D37:$DT38,2,FALSE)) -> 0 | G12: =IF(G$4<'Platform Assumptions'!$D$37,0,HLOOKUP(G$4,'Platform Assumptions'!$D37:$DT38,2,FALSE)) -> 0 | H12: =IF(H$4<'Platform Assumptions'!$D$37,0,HLOOKUP(H$4,'Platform Assumptions'!$D37:$DT38,2,FALSE)) -> 0 | I12: =IF(I$4<'Platform Assumptions'!$D$37,0,HLOOKUP(I$4,'Platform Assumptions'!$D37:$DT38,2,FALSE)) -> 0 | J12: =IF(J$4<'Platform Assumptions'!$D$37,0,HLOOKUP(J$4,'Platform Assumptions'!$D37:$DT38,2,FALSE)) -> 0 | K12: =IF(K$4<'Platform Assumptions'!$D$37,0,HLOOKUP(K$4,'Platform Assumptions'!$D37:$DT38,2,FALSE)) -> 0 | L12: =IF(L$4<'Platform Assumptions'!$D$37,0,HLOOKUP(L$4,'Platform Assumptions'!$D37:$DT38,2,FALSE)) -> 0 | ... DU12: =IF(DU$4<'Platform Assumptions'!$D$37,0,HLOOKUP(DU$4,'Platform Assumptions'!$D37:$DT38,2,FALSE)) -> 0
C13: =C12+1 -> 7 | D13: =SUM(E13:DU13) -> 3339552 | E13: =IF(E$4<'Platform Assumptions'!$D$40,0,HLOOKUP(E$4,'Platform Assumptions'!$D40:$DT41,2,FALSE)) -> 0 | F13: =IF(F$4<'Platform Assumptions'!$D$40,0,HLOOKUP(F$4,'Platform Assumptions'!$D40:$DT41,2,FALSE)) -> 0 | G13: =IF(G$4<'Platform Assumptions'!$D$40,0,HLOOKUP(G$4,'Platform Assumptions'!$D40:$DT41,2,FALSE)) -> 0 | H13: =IF(H$4<'Platform Assumptions'!$D$40,0,HLOOKUP(H$4,'Platform Assumptions'!$D40:$DT41,2,FALSE)) -> 0 | I13: =IF(I$4<'Platform Assumptions'!$D$40,0,HLOOKUP(I$4,'Platform Assumptions'!$D40:$DT41,2,FALSE)) -> 0 | J13: =IF(J$4<'Platform Assumptions'!$D$40,0,HLOOKUP(J$4,'Platform Assumptions'!$D40:$DT41,2,FALSE)) -> 0 | K13: =IF(K$4<'Platform Assumptions'!$D$40,0,HLOOKUP(K$4,'Platform Assumptions'!$D40:$DT41,2,FALSE)) -> 0 | L13: =IF(L$4<'Platform Assumptions'!$D$40,0,HLOOKUP(L$4,'Platform Assumptions'!$D40:$DT41,2,FALSE)) -> 0 | ... DU13: =IF(DU$4<'Platform Assumptions'!$D$40,0,HLOOKUP(DU$4,'Platform Assumptions'!$D40:$DT41,2,FALSE)) -> 6750
C14: =C13+1 -> 8 | D14: =SUM(E14:DU14) -> 105000 | E14: =IF(E$4<'Platform Assumptions'!$D$43,0,HLOOKUP(E$4,'Platform Assumptions'!$D43:$DT44,2,FALSE)) -> 0 | F14: =IF(F$4<'Platform Assumptions'!$D$43,0,HLOOKUP(F$4,'Platform Assumptions'!$D43:$DT44,2,FALSE)) -> 0 | G14: =IF(G$4<'Platform Assumptions'!$D$43,0,HLOOKUP(G$4,'Platform Assumptions'!$D43:$DT44,2,FALSE)) -> 0 | H14: =IF(H$4<'Platform Assumptions'!$D$43,0,HLOOKUP(H$4,'Platform Assumptions'!$D43:$DT44,2,FALSE)) -> 0 | I14: =IF(I$4<'Platform Assumptions'!$D$43,0,HLOOKUP(I$4,'Platform Assumptions'!$D43:$DT44,2,FALSE)) -> 0 | J14: =IF(J$4<'Platform Assumptions'!$D$43,0,HLOOKUP(J$4,'Platform Assumptions'!$D43:$DT44,2,FALSE)) -> 0 | K14: =IF(K$4<'Platform Assumptions'!$D$43,0,HLOOKUP(K$4,'Platform Assumptions'!$D43:$DT44,2,FALSE)) -> 0 | L14: =IF(L$4<'Platform Assumptions'!$D$43,0,HLOOKUP(L$4,'Platform Assumptions'!$D43:$DT44,2,FALSE)) -> 0 | ... DU14: =IF(DU$4<'Platform Assumptions'!$D$43,0,HLOOKUP(DU$4,'Platform Assumptions'!$D43:$DT44,2,FALSE)) -> 0
C15: =C14+1 -> 9 | D15: =SUM(E15:DU15) -> 3299052 | E15: =IF(E$4<'Platform Assumptions'!$D$46,0,HLOOKUP(E$4,'Platform Assumptions'!$D46:$DT47,2,FALSE)) -> 0 | F15: =IF(F$4<'Platform Assumptions'!$D$46,0,HLOOKUP(F$4,'Platform Assumptions'!$D46:$DT47,2,FALSE)) -> 0 | G15: =IF(G$4<'Platform Assumptions'!$D$46,0,HLOOKUP(G$4,'Platform Assumptions'!$D46:$DT47,2,FALSE)) -> 0 | H15: =IF(H$4<'Platform Assumptions'!$D$46,0,HLOOKUP(H$4,'Platform Assumptions'!$D46:$DT47,2,FALSE)) -> 0 | I15: =IF(I$4<'Platform Assumptions'!$D$46,0,HLOOKUP(I$4,'Platform Assumptions'!$D46:$DT47,2,FALSE)) -> 0 | J15: =IF(J$4<'Platform Assumptions'!$D$46,0,HLOOKUP(J$4,'Platform Assumptions'!$D46:$DT47,2,FALSE)) -> 0 | K15: =IF(K$4<'Platform Assumptions'!$D$46,0,HLOOKUP(K$4,'Platform Assumptions'!$D46:$DT47,2,FALSE)) -> 0 | L15: =IF(L$4<'Platform Assumptions'!$D$46,0,HLOOKUP(L$4,'Platform Assumptions'!$D46:$DT47,2,FALSE)) -> 0 | ... DU15: =IF(DU$4<'Platform Assumptions'!$D$46,0,HLOOKUP(DU$4,'Platform Assumptions'!$D46:$DT47,2,FALSE)) -> 6750
C16: =C15+1 -> 10 | D16: =SUM(E16:DU16) -> 105000 | E16: =IF(E$4<'Platform Assumptions'!$D$49,0,HLOOKUP(E$4,'Platform Assumptions'!$D49:$DT50,2,FALSE)) -> 0 | F16: =IF(F$4<'Platform Assumptions'!$D$49,0,HLOOKUP(F$4,'Platform Assumptions'!$D49:$DT50,2,FALSE)) -> 0 | G16: =IF(G$4<'Platform Assumptions'!$D$49,0,HLOOKUP(G$4,'Platform Assumptions'!$D49:$DT50,2,FALSE)) -> 0 | H16: =IF(H$4<'Platform Assumptions'!$D$49,0,HLOOKUP(H$4,'Platform Assumptions'!$D49:$DT50,2,FALSE)) -> 0 | I16: =IF(I$4<'Platform Assumptions'!$D$49,0,HLOOKUP(I$4,'Platform Assumptions'!$D49:$DT50,2,FALSE)) -> 0 | J16: =IF(J$4<'Platform Assumptions'!$D$49,0,HLOOKUP(J$4,'Platform Assumptions'!$D49:$DT50,2,FALSE)) -> 0 | K16: =IF(K$4<'Platform Assumptions'!$D$49,0,HLOOKUP(K$4,'Platform Assumptions'!$D49:$DT50,2,FALSE)) -> 0 | L16: =IF(L$4<'Platform Assumptions'!$D$49,0,HLOOKUP(L$4,'Platform Assumptions'!$D49:$DT50,2,FALSE)) -> 0 | ... DU16: =IF(DU$4<'Platform Assumptions'!$D$49,0,HLOOKUP(DU$4,'Platform Assumptions'!$D49:$DT50,2,FALSE)) -> 0
C17: Total Project Level Cash Flows | D17: =SUM(E17:DU17) -> 17330760 | E17: =SUM(E7:E16) -> 46666.667 | F17: =SUM(F7:F16) -> -3333.3333 | G17: =SUM(G7:G16) -> -3333.3333 | H17: =SUM(H7:H16) -> 43333.333 | I17: =SUM(I7:I16) -> -6666.6667 | J17: =SUM(J7:J16) -> -6666.6667 | K17: =SUM(K7:K16) -> 49583.333 | L17: =SUM(L7:L16) -> -416.66667 | ... DU17: =SUM(DU7:DU16) -> 20250
C19: Central Overhead Costs | D19: =SUM(E19:DU19) -> -5041666.7 | E19: =-'Platform Assumptions'!$I$7 -> -41666.667 | F19: =-'Platform Assumptions'!$I$7 -> -41666.667 | G19: =-'Platform Assumptions'!$I$7 -> -41666.667 | H19: =-'Platform Assumptions'!$I$7 -> -41666.667 | I19: =-'Platform Assumptions'!$I$7 -> -41666.667 | J19: =-'Platform Assumptions'!$I$7 -> -41666.667 | K19: =-'Platform Assumptions'!$I$7 -> -41666.667 | L19: =-'Platform Assumptions'!$I$7 -> -41666.667 | ... DU19: =-'Platform Assumptions'!$I$7 -> -41666.667
C21: Net Cash Flows | D21: =SUM(E21:DU21) -> 12289093 | E21: =E17+E19 -> 5000 | F21: =F17+F19 -> -45000 | G21: =G17+G19 -> -45000 | H21: =H17+H19 -> 1666.6667 | I21: =I17+I19 -> -48333.333 | J21: =J17+J19 -> -48333.333 | K21: =K17+K19 -> 7916.6667 | L21: =L17+L19 -> -42083.333 | ... DU21: =DU17+DU19 -> -21416.667
E23: =+E21 -> 5000 | F23: =+F21+E23 -> -40000 | G23: =+G21+F23 -> -85000 | H23: =+H21+G23 -> -83333.333 | I23: =+I21+H23 -> -131666.67 | J23: =+J21+I23 -> -180000 | K23: =+K21+J23 -> -172083.33 | L23: =+L21+K23 -> -214166.67 | M23: =+M21+L23 -> -256250 | ... DU23: =+DU21+DT23 -> 12289093

Sheet Single Project Cash Flows--->
M4: Description
M5: This model sets out the economics for a single “Commons” project and illustrates how a multi-stakeholder development can be structured without The Commons owning land or funding construction. The project follows a four-stage process designed to align landowners, entitlement capital, developers and future residents.
M9: 1 - Option Phase: The Commons enters into an option agreement with a farmer, allowing the land to remain in agricultural use while the project is explored. The farmer continues to earn farming income during this period. The Commons’ role is to articulate the vision, align incentives, and secure an Entitlement Investor to take the project forward.
M13: 2 - Entitlement Phase: The Entitlement Investor funds and manages the planning and entitlement process. Importantly, they do not acquire the land upfront and do not pay a traditional option fee. Instead, their economic upside is back-ended and capped, realised through the uplift in land value once entitlements are secured. This limits capital at risk while preserving strong returns if successful.
M17: 3 - Development Phase: Following successful entitlement, a developer steps in and pays out the Entitlement Investor. The residual uplift in land value (net of this payment) is contributed as equity by the landowner and The Commons. The developer funds construction, sells the homes, and earns a development return. The Commons and the landowner receive capital formation and delivery fees to ensure alignment and oversight during build-out.
M21: 4 - Operations Phase: Once occupied, residents pay three transparent, ongoing charges: (i) a stewardship fee to The Commons, (ii) service charges covering shared operating costs, and (iii) a land payment to the landowner. These payments support long-term community management and provide the landowner with a stable, inflation-linked income that materially exceeds traditional agricultural yields.

Sheet Single Project Assumptions
B3: TIMING ASSUMPTIONS
B5: Model Timing | F5: Key
B6: Model Start Date | D6: 46387 | F6: INPUTS
B7: Exit Date | D7: =T13 -> 49765 | F7: OUTPUTS
B8: Hold Period (years) | D8: =YEARFRAC(D6,D7) -> 9.25
B10: Land Option | F10: Entitlement Phase | J10: Development Phase | N10: Residential Sales | R10: Operational Phase
B11: Option Date | D11: =D6 -> 46387 | F11: Entitement Investor Step In Date | H11: =D15 -> 46568 | J11: Developer Step In Date | L11: =H15 -> 47118 | N11: Months to Sales Start (from const. start) | P11: 18 | R11: Operational Start Date | T11: =L15 -> 47938
B12: Option Duration (months) | D12: 18 | F12: Entltlement Period | H12: 12 | J12: Months to Development Start | L12: 3 | N12: Sales Start Date | P12: =EOMONTH(L13,P11) -> 47756 | R12: Hold Period | T12: 60
B13: Option Expiration Date | D13: =EOMONTH(D11,D12) -> 46934 | F13: Entitlements Obtained | H13: =EOMONTH(H11,H12) -> 46934 | J13: Development Start Date | L13: =EOMONTH(L11,L12) -> 47208 | N13: Sell Out Months | P13: 18 | R13: Exit Date | T13: =EOMONTH(T11,T12) -> 49765
B14: Months to Engage Entitlement Investor | D14: 6 | F14: Months to Engage Developer | H14: 6 | J14: Development Period | L14: 24 | N14: Sales End Date | P14: =EOMONTH(P12,P13) -> 48304
B15: Entitlement Investor Step In Date | D15: =EOMONTH(D11,D14) -> 46568 | F15: Developer Step In / Entitlement Exit | H15: =EOMONTH(H13,H14) -> 47118 | J15: Development Completion Date | L15: =EOMONTH(L13,L14) -> 47938 | N15: Sales Velocity (units / month) | P15: =D21/P13 -> 8.3333333
B17: PROJECT AND COST ASSUMPTIONS
B19: Residential Units and Areas | F19: Entitlement Costs | J19: Developer Costs | N19: Ownership Split at Development
B20: Land Area (acres) | D20: 50 | F20: Entitlment Costs / Unit | H20: 25000 | J20: Land Entry Value | L20: =H39-H41 -> 1875000 | N20: Land (Farmer) | P20: =((L20+L22)/L31)*Q20 -> 0.0059649741 | Q20: 0.5
B21: Number of Units | D21: 150 | F21: Total Entitlement Costs | H21: =H20*D21 -> 3750000 | J21: Acquisition Costs % | L21: 0.015 | N21: Land (The Commons) | P21: =P20/Q20*Q21 -> 0.0059649741 | Q21: =1-Q20 -> 0.5
B22: Average Unit Size sq ft | D22: 2500 | J22: Acquisition Costs | L22: =L20*L21 -> 28125 | N22: Construction (Developer) | P22: =1-P20-P21 -> 0.98807005
B23: Total Residential Area sq ft | D23: =D21*D22 -> 375000 | J23: Infrastructure / Unit | L23: 100000 | N23: Total Ownership | P23: =SUM(P20:P22) -> 1
J24: Hard Costs / Unit | L24: 750000
B25: Amenities | J25: Soft Costs % | L25: 0.15
B26: Amenity Area sq ft | D26: 50000 | J26: Soft Costs | L26: =L25*SUM(L23:L24) -> 127500 | N26: Sales Costs
J27: Contingency % | L27: 0.075 | N27: Marketing % of GDV | P27: 0.01
B28: The Commons Controlled / Management | J28: Contingency | L28: =L27*(SUM(L26,L24,L23)) -> 73312.5 | N28: Marketing Costs | P28: =P27*L38 -> 2250000
B29: Total Area sq ft | D29: 10000 | J29: Total Costs Per Unit | L29: =SUM(L23,L24,L26,L28) -> 1050812.5 | N29: Agents Fees % of GDV | P29: 0.04
J30: Total Development Costs | L30: =L29*D21 -> 157621875 | N30: Agents Fees | P30: =P29*L38 -> 9000000
J31: All-In Cost Basis | L31: =L20+L22+L30 -> 159525000
J32: All-In Costs Basis / Unit | L32: =L31/D21 -> 1063500
B34: PRIICNG AND OPERATING ASSUMPTIONS
B36: Day 1 Land Value | F36: Entitled Land Value | J36: Residential Sales Prices
B37: Land Area (acres) | D37: =D20 -> 50 | F37: Land Area (acres) | H37: =D37 -> 50 | J37: Average Sale Price / Unit | L37: 1500000
B38: Day 1 Value / Acre | D38: 20000 | F38: Entitled Land Value / Acre | H38: 150000 | J38: Total Reidential Sales | L38: =L37*D21 -> 225000000
B39: Day 1 Land Value | D39: =D37*D38 -> 1000000 | F39: Entitled Land Value | H39: =H37*H38 -> 7500000 | J39: Sale Price / sq ft | L39: =L38/D23 -> 600
F40: Entitlement Investor Equity Multiple | H40: 1.5 | J40: Sales Velocity (units / month) | L40: =P15 -> 8.3333333
F41: Entitlement Investor Implied Exit Value | H41: =H40*H21 -> 5625000 | J41: Deposit % | L41: 0.15
F42: Sales Costs | H42: 0.01 | J42: Deposit / Unit | L42: =L41*L37 -> 225000
B45: FEE ASSUMPTIONS AND ECONOMICS
B47: Farmer Economics | F47: The Commons Fees - Options and Entitlement | J47: The Commons Fees - Development | N47: The Commons Fees - Operational | R47: Service Charges
B48: Day 1 Land Value | D48: =D39 -> 1000000 | F48: Option Stage Fees | J48: Development Stage Fees | N48: Operational Stage Fees | R48: Operational Stage Service Charges
B49: Crop Yield | D49: 0.02 | F49: Land Access / Structuring Fee | H49: 50000 | J49: Capital Formation (% GDV) | L49: 0.01 | N49: Operating Fee (per unit per month) | P49: 150 | R49: Service Charges (per unit per month) | T49: 200
B50: Crop Yield Income | D50: =D48*D49 -> 20000 | F50: Date Paid | H50: =D11 -> 46387 | J50: Capital Formation Fee | L50: =L49*L38 -> 2250000 | N50: Operating Fee (per unit per year) | P50: =P49*12 -> 1800 | R50: Service Charges (per unit per year) | T50: =T49*12 -> 2400
B51: Target Yield At Stabilizaton | D51: 0.15 | F51: Costs to Secure Entitlement Investor | H51: 20000 | J51: Date Paid | L51: =L11 -> 47118 | N51: Operating Fee per month | P51: =P49*D21 -> 22500 | R51: Service Charges per month | T51: =T49*D21 -> 30000
...

Sheet Rolled Up Cash Flows
D3: Year | E3: =YEAR(E4) -> 2026 | F3: =YEAR(F4) -> 2027 | G3: =YEAR(G4) -> 2027 | H3: =YEAR(H4) -> 2027 | I3: =YEAR(I4) -> 2027 | J3: =YEAR(J4) -> 2027 | K3: =YEAR(K4) -> 2027 | L3: =YEAR(L4) -> 2027 | ... DU3: =YEAR(DU4) -> 2036
C4: Rolled Up Cash Flows Per Stakeholder | D4: Total | E4: ='Single Project Assumptions'!D11 -> 46387 | F4: =EOMONTH(E4,1) -> 46418 | G4: =EOMONTH(F4,1) -> 46446 | H4: =EOMONTH(G4,1) -> 46477 | I4: =EOMONTH(H4,1) -> 46507 | J4: =EOMONTH(I4,1) -> 46538 | K4: =EOMONTH(J4,1) -> 46568 | L4: =EOMONTH(K4,1) -> 46599 | M4: =EOMONTH(L4,1) -> 46630 | ... DU4: =EOMONTH(DT4,1) -> 50040
C6: Landowner Cash Flows
C7: Day 1 Land Value | D7: =SUM(E7:DU7) -> -1000000 | E7: =IF(E$4='Single Project Assumptions'!$D$11,-'Single Project Assumptions'!$D$48,0) -> -1000000 | F7: =IF(F$4='Single Project Assumptions'!$D$11,-'Single Project Assumptions'!$D$48,0) -> 0 | G7: =IF(G$4='Single Project Assumptions'!$D$11,-'Single Project Assumptions'!$D$48,0) -> 0 | H7: =IF(H$4='Single Project Assumptions'!$D$11,-'Single Project Assumptions'!$D$48,0) -> 0 | I7: =IF(I$4='Single Project Assumptions'!$D$11,-'Single Project Assumptions'!$D$48,0) -> 0 | J7: =IF(J$4='Single Project Assumptions'!$D$11,-'Single Project Assumptions'!$D$48,0) -> 0 | K7: =IF(K$4='Single Project Assumptions'!$D$11,-'Single Project Assumptions'!$D$48,0) -> 0 | L7: =IF(L$4='Single Project Assumptions'!$D$11,-'Single Project Assumptions'!$D$48,0) -> 0 | ... DU7: =IF(DU$4='Single Project Assumptions'!$D$11,-'Single Project Assumptions'!$D$48,0) -> 0
C8: Option Phase - Farming Yield | D8: =SUM(E8:DU8) -> 10000 | E8: ='Option Phase'!E7 -> 1666.6667 | F8: ='Option Phase'!F7 -> 1666.6667 | G8: ='Option Phase'!G7 -> 1666.6667 | H8: ='Option Phase'!H7 -> 1666.6667 | I8: ='Option Phase'!I7 -> 1666.6667 | J8: ='Option Phase'!J7 -> 1666.6667 | K8: ='Option Phase'!K7 -> 0 | L8: ='Option Phase'!L7 -> 0 | ... DU8: ='Option Phase'!DU7 -> 0
C9: Option Phase - Option Payment | D9: =SUM(E9:DU9) -> -50000 | E9: ='Option Phase'!E8 -> -50000 | F9: ='Option Phase'!F8 -> 0 | G9: ='Option Phase'!G8 -> 0 | H9: ='Option Phase'!H8 -> 0 | I9: ='Option Phase'!I8 -> 0 | J9: ='Option Phase'!J8 -> 0 | K9: ='Option Phase'!K8 -> 0 | L9: ='Option Phase'!L8 -> 0 | ... DU9: ='Option Phase'!DU8 -> 0
C10: Entitlement Phase - Farming Yield | D10: =SUM(E10:DU10) -> 20000 | E10: ='Entitlement Phase'!E18 -> 0 | F10: ='Entitlement Phase'!F18 -> 0 | G10: ='Entitlement Phase'!G18 -> 0 | H10: ='Entitlement Phase'!H18 -> 0 | I10: ='Entitlement Phase'!I18 -> 0 | J10: ='Entitlement Phase'!J18 -> 0 | K10: ='Entitlement Phase'!K18 -> 1666.6667 | L10: ='Entitlement Phase'!L18 -> 1666.6667 | ... DU10: ='Entitlement Phase'!DU18 -> 0
C11: Development Phase - Capital Formation Fees | D11: =SUM(E11:DU11) -> 900000 | E11: ='Development Phase'!E37 -> 0 | F11: ='Development Phase'!F37 -> 0 | G11: ='Development Phase'!G37 -> 0 | H11: ='Development Phase'!H37 -> 0 | I11: ='Development Phase'!I37 -> 0 | J11: ='Development Phase'!J37 -> 0 | K11: ='Development Phase'!K37 -> 0 | L11: ='Development Phase'!L37 -> 0 | ... DU11: ='Development Phase'!DU37 -> 0
C12: Development Phase - Delivery Fees | D12: =SUM(E12:DU12) -> 157621.88 | E12: ='Development Phase'!E41 -> 0 | F12: ='Development Phase'!F41 -> 0 | G12: ='Development Phase'!G41 -> 0 | H12: ='Development Phase'!H41 -> 0 | I12: ='Development Phase'!I41 -> 0 | J12: ='Development Phase'!J41 -> 0 | K12: ='Development Phase'!K41 -> 0 | L12: ='Development Phase'!L41 -> 0 | ... DU12: ='Development Phase'!DU41 -> 0
C13: Development Phase - Equity Participation | D13: =SUM(E13:DU13) -> 1342119.2 | E13: ='Development Phase'!E33 -> 0 | F13: ='Development Phase'!F33 -> 0 | G13: ='Development Phase'!G33 -> 0 | H13: ='Development Phase'!H33 -> 0 | I13: ='Development Phase'!I33 -> 0 | J13: ='Development Phase'!J33 -> 0 | K13: ='Development Phase'!K33 -> 0 | L13: ='Development Phase'!L33 -> 0 | ... DU13: ='Development Phase'!DU33 -> 0
C14: Operational Phase - Stewardship Fees | D14: =SUM(E14:DU14) -> 704166.67 | E14: ='Operational Phase'!E27 -> 0 | F14: ='Operational Phase'!F27 -> 0 | G14: ='Operational Phase'!G27 -> 0 | H14: ='Operational Phase'!H27 -> 0 | I14: ='Operational Phase'!I27 -> 0 | J14: ='Operational Phase'!J27 -> 0 | K14: ='Operational Phase'!K27 -> 0 | L14: ='Operational Phase'!L27 -> 0 | ... DU14: ='Operational Phase'!DU27 -> 0
C15: Total Landowner Cash Flows | D15: =SUM(E15:DU15) -> 2083907.7 | E15: =SUM(E7:E14) -> -1048333.3 | F15: =SUM(F7:F14) -> 1666.6667 | G15: =SUM(G7:G14) -> 1666.6667 | H15: =SUM(H7:H14) -> 1666.6667 | I15: =SUM(I7:I14) -> 1666.6667 | J15: =SUM(J7:J14) -> 1666.6667 | K15: =SUM(K7:K14) -> 1666.6667 | L15: =SUM(L7:L14) -> 1666.6667 | ... DU15: =SUM(DU7:DU14) -> 0
C16: Annualized Yield on Day 1 Land Value | D16: =AVERAGE(E16:DU16) -> 0.072809917 | E16: =F16 -> 0.02 | F16: =(SUM(F8,F10,F14)*12)/-$D$7 -> 0.02 | G16: =(SUM(G8,G10,G14)*12)/-$D$7 -> 0.02 | H16: =(SUM(H8,H10,H14)*12)/-$D$7 -> 0.02 | I16: =(SUM(I8,I10,I14)*12)/-$D$7 -> 0.02 | J16: =(SUM(J8,J10,J14)*12)/-$D$7 -> 0.02 | K16: =(SUM(K8,K10,K14)*12)/-$D$7 -> 0.02 | L16: =(SUM(L8,L10,L14)*12)/-$D$7 -> 0.02 | M16: =(SUM(M8,M10,M14)*12)/-$D$7 -> 0.02 | ... DU16: =(SUM(DU8,DU10,DU14)*12)/-$D$7 -> 0
C17: Peak Equity | D17: =-MIN(E17:DU17) -> 1048333.3 | E17: =E15 -> -1048333.3 | F17: =F15+E17 -> -1046666.7 | G17: =G15+F17 -> -1045000 | H17: =H15+G17 -> -1043333.3 | I17: =I15+H17 -> -1041666.7 | J17: =J15+I17 -> -1040000 | K17: =K15+J17 -> -1038333.3 | L17: =L15+K17 -> -1036666.7 | M17: =M15+L17 -> -1035000 | ... DU17: =DU15+DT17 -> 2083907.7
C18: IRR | D18: =XIRR(E15:DU15,E4:DU4,0.1) -> 0.33907558
C19: Equity Multiple | D19: =D15/D17+1 -> 2.9878293
C21: The Commons Cash Flows
C22: Option Phase - Option Payment | D22: =SUM(E22:DU22) -> 50000 | E22: ='Option Phase'!E12 -> 50000 | F22: ='Option Phase'!F12 -> 0 | G22: ='Option Phase'!G12 -> 0 | H22: ='Option Phase'!H12 -> 0 | I22: ='Option Phase'!I12 -> 0 | J22: ='Option Phase'!J12 -> 0 | K22: ='Option Phase'!K12 -> 0 | L22: ='Option Phase'!L12 -> 0 | ... DU22: ='Option Phase'!DU12 -> 0
C23: Option Phase - Costs to Secure Entitlement Investor | D23: =SUM(E23:DU23) -> -20000 | E23: ='Option Phase'!E13 -> -3333.3333 | F23: ='Option Phase'!F13 -> -3333.3333 | G23: ='Option Phase'!G13 -> -3333.3333 | H23: ='Option Phase'!H13 -> -3333.3333 | I23: ='Option Phase'!I13 -> -3333.3333 | J23: ='Option Phase'!J13 -> -3333.3333 | K23: ='Option Phase'!K13 -> 0 | L23: ='Option Phase'!L13 -> 0 | ... DU23: ='Option Phase'!DU13 -> 0
C24: Entitlement Phase - Entitlement Fee | D24: =SUM(E24:DU24) -> 75000 | E24: =-'Entitlement Phase'!E7 -> 0 | F24: =-'Entitlement Phase'!F7 -> 0 | G24: =-'Entitlement Phase'!G7 -> 0 | H24: =-'Entitlement Phase'!H7 -> 0 | I24: =-'Entitlement Phase'!I7 -> 0 | J24: =-'Entitlement Phase'!J7 -> 0 | K24: =-'Entitlement Phase'!K7 -> 6250 | L24: =-'Entitlement Phase'!L7 -> 6250 | ... DU24: =-'Entitlement Phase'!DU7 -> 0
C25: Entitlement Phase - Entitlement Success Fee | D25: =SUM(E25:DU25) -> 37500 | E25: =-'Entitlement Phase'!E8 -> 0 | F25: =-'Entitlement Phase'!F8 -> 0 | G25: =-'Entitlement Phase'!G8 -> 0 | H25: =-'Entitlement Phase'!H8 -> 0 | I25: =-'Entitlement Phase'!I8 -> 0 | J25: =-'Entitlement Phase'!J8 -> 0 | K25: =-'Entitlement Phase'!K8 -> 0 | L25: =-'Entitlement Phase'!L8 -> 0 | ... DU25: =-'Entitlement Phase'!DU8 -> 0
C26: Development Phase - Capital Formation Fee | D26: =SUM(E26:DU26) -> 1350000 | E26: ='Development Phase'!E38 -> 0 | F26: ='Development Phase'!F38 -> 0 | G26: ='Development Phase'!G38 -> 0 | H26: ='Development Phase'!H38 -> 0 | I26: ='Development Phase'!I38 -> 0 | J26: ='Development Phase'!J38 -> 0 | K26: ='Development Phase'!K38 -> 0 | L26: ='Development Phase'!L38 -> 0 | ... DU26: ='Development Phase'!DU38 -> 0
C27: Development Phase - Delivery Fee | D27: =SUM(E27:DU27) -> 236432.81 | E27: ='Development Phase'!E42 -> 0 | F27: ='Development Phase'!F42 -> 0 | G27: ='Development Phase'!G42 -> 0 | H27: ='Development Phase'!H42 -> 0 | I27: ='Development Phase'!I42 -> 0 | J27: ='Development Phase'!J42 -> 0 | K27: ='Development Phase'!K42 -> 0 | L27: ='Development Phase'!L42 -> 0 | ... DU27: ='Development Phase'!DU42 -> 0
C28: Development Phase - Equity Participation | D28: =SUM(E28:DU28) -> 1342119.2 | E28: ='Development Phase'!E34 -> 0 | F28: ='Development Phase'!F34 -> 0 | G28: ='Development Phase'!G34 -> 0 | H28: ='Development Phase'!H34 -> 0 | I28: ='Development Phase'!I34 -> 0 | J28: ='Development Phase'!J34 -> 0 | K28: ='Development Phase'!K34 -> 0 | L28: ='Development Phase'!L34 -> 0 | ... DU28: ='Development Phase'!DU34 -> 0
C29: Operational Phase - Operations Fees | D29: =SUM(E29:DU29) -> 1267500 | E29: ='Operational Phase'!E15 -> 0 | F29: ='Operational Phase'!F15 -> 0 | G29: ='Operational Phase'!G15 -> 0 | H29: ='Operational Phase'!H15 -> 0 | I29: ='Operational Phase'!I15 -> 0 | J29: ='Operational Phase'!J15 -> 0 | K29: ='Operational Phase'!K15 -> 0 | L29: ='Operational Phase'!L15 -> 0 | ... DU29: ='Operational Phase'!DU15 -> 0
C30: Operational Phase - Operations Costs | D30: =SUM(E30:DU30) -> -945000 | E30: ='Operational Phase'!E16 -> 0 | F30: ='Operational Phase'!F16 -> 0 | G30: ='Operational Phase'!G16 -> 0 | H30: ='Operational Phase'!H16 -> 0 | I30: ='Operational Phase'!I16 -> 0 | J30: ='Operational Phase'!J16 -> 0 | K30: ='Operational Phase'!K16 -> 0 | L30: ='Operational Phase'!L16 -> 0 | ... DU30: ='Operational Phase'!DU16 -> 0
B31: c | C31: The Commons Cash Flows | D31: =SUM(E31:DU31) -> 3393552 | E31: =SUM(E22:E30) -> 46666.667 | F31: =SUM(F22:F30) -> -3333.3333 | G31: =SUM(G22:G30) -> -3333.3333 | H31: =SUM(H22:H30) -> -3333.3333 | I31: =SUM(I22:I30) -> -3333.3333 | J31: =SUM(J22:J30) -> -3333.3333 | K31: =SUM(K22:K30) -> 6250 | L31: =SUM(L22:L30) -> 6250 | ... DU31: =SUM(DU22:DU30) -> 0
C32: Peak Equity | D32: =-MIN(E32:DU32) -> -30000 | E32: =E31 -> 46666.667 | F32: =F31+E32 -> 43333.333 | G32: =G31+F32 -> 40000 | H32: =H31+G32 -> 36666.667 | I32: =I31+H32 -> 33333.333 | J32: =J31+I32 -> 30000 | K32: =K31+J32 -> 36250 | L32: =L31+K32 -> 42500 | M32: =M31+L32 -> 48750 | ... DU32: =DU31+DT32 -> 3393552
C33: IRR | D33: na
C34: Equity Multiple | D34: na
C36: Entitlement Investor Cash Flow
C37: Entitlement Investor Net Cash Flow | D37: =SUM(E37:DU37) -> 1706250 | E37: ='Entitlement Phase'!E11 -> 0 | F37: ='Entitlement Phase'!F11 -> 0 | G37: ='Entitlement Phase'!G11 -> 0 | H37: ='Entitlement Phase'!H11 -> 0 | I37: ='Entitlement Phase'!I11 -> 0 | J37: ='Entitlement Phase'!J11 -> 0 | K37: ='Entitlement Phase'!K11 -> -318750 | L37: ='Entitlement Phase'!L11 -> -318750 | ... DU37: ='Entitlement Phase'!DU11 -> 0
C38: Peak Equity | D38: =-MIN(E38:DU38) -> 3862500 | E38: =E37 -> 0 | F38: =F37+E38 -> 0 | G38: =G37+F38 -> 0 | H38: =H37+G38 -> 0 | I38: =I37+H38 -> 0 | J38: =J37+I38 -> 0 | K38: =K37+J38 -> -318750 | L38: =L37+K38 -> -637500 | M38: =M37+L38 -> -956250 | ... DU38: =DU37+DT38 -> 1706250
C39: IRR | D39: ='Entitlement Phase'!D13 -> 0.41443852
C40: Equity Multiple | D40: ='Entitlement Phase'!D14 -> 1.4417476
C42: Development Investor Cash Flow
C43: Developer Net Cash Flow | D43: =SUM(E43:DU43) -> 56340457 | E43: ='Development Phase'!E27 -> 0 | F43: ='Development Phase'!F27 -> 0 | G43: ='Development Phase'!G27 -> 0 | H43: ='Development Phase'!H27 -> 0 | I43: ='Development Phase'!I27 -> 0 | J43: ='Development Phase'!J27 -> 0 | K43: ='Development Phase'!K27 -> 0 | L43: ='Development Phase'!L27 -> 0 | ... DU43: ='Development Phase'!DU27 -> 0
C44: Peak Equity | D44: =-MIN(E44:DU44) -> 1.5485952e+08 | E44: =E43 -> 0 | F44: =F43+E44 -> 0 | G44: =G43+F44 -> 0 | H44: =H43+G44 -> 0 | I44: =I43+H44 -> 0 | J44: =J43+I44 -> 0 | K44: =K43+J44 -> 0 | L44: =L43+K44 -> 0 | M44: =M43+L44 -> 0 | ... DU44: =DU43+DT44 -> 56340457
C45: IRR | D45: ='Development Phase'!D29 -> 0.22888162
C46: Equity Multiple | D46: ='Development Phase'!D30 -> 1.3638166
...

Sheet Option Phase
D3: Year | E3: =YEAR(E4) -> 2026 | F3: =YEAR(F4) -> 2027 | G3: =YEAR(G4) -> 2027 | H3: =YEAR(H4) -> 2027 | I3: =YEAR(I4) -> 2027 | J3: =YEAR(J4) -> 2027 | K3: =YEAR(K4) -> 2027 | L3: =YEAR(L4) -> 2027 | ... DU3: =YEAR(DU4) -> 2036
C4: Option Phase Cash Flow | D4: Total | E4: ='Single Project Assumptions'!D11 -> 46387 | F4: =EOMONTH(E4,1) -> 46418 | G4: =EOMONTH(F4,1) -> 46446 | H4: =EOMONTH(G4,1) -> 46477 | I4: =EOMONTH(H4,1) -> 46507 | J4: =EOMONTH(I4,1) -> 46538 | K4: =EOMONTH(J4,1) -> 46568 | L4: =EOMONTH(K4,1) -> 46599 | M4: =EOMONTH(L4,1) -> 46630 | ... DU4: =EOMONTH(DT4,1) -> 50040
C6: Landonwer
C7: Landower (Farming Land) | D7: =SUM(E7:DU7) -> 10000 | E7: =IF(AND(E$4>='Single Project Assumptions'!$D$11,'Option Phase'!E$4<'Single Project Assumptions'!$D$15),'Single Project Assumptions'!$D$50/12,0) -> 1666.6667 | F7: =IF(AND(F$4>='Single Project Assumptions'!$D$11,'Option Phase'!F$4<'Single Project Assumptions'!$D$15),'Single Project Assumptions'!$D$50/12,0) -> 1666.6667 | G7: =IF(AND(G$4>='Single Project Assumptions'!$D$11,'Option Phase'!G$4<'Single Project Assumptions'!$D$15),'Single Project Assumptions'!$D$50/12,0) -> 1666.6667 | H7: =IF(AND(H$4>='Single Project Assumptions'!$D$11,'Option Phase'!H$4<'Single Project Assumptions'!$D$15),'Single Project Assumptions'!$D$50/12,0) -> 1666.6667 | I7: =IF(AND(I$4>='Single Project Assumptions'!$D$11,'Option Phase'!I$4<'Single Project Assumptions'!$D$15),'Single Project Assumptions'!$D$50/12,0) -> 1666.6667 | J7: =IF(AND(J$4>='Single Project Assumptions'!$D$11,'Option Phase'!J$4<'Single Project Assumptions'!$D$15),'Single Project Assumptions'!$D$50/12,0) -> 1666.6667 | K7: =IF(AND(K$4>='Single Project Assumptions'!$D$11,'Option Phase'!K$4<'Single Project Assumptions'!$D$15),'Single Project Assumptions'!$D$50/12,0) -> 0 | L7: =IF(AND(L$4>='Single Project Assumptions'!$D$11,'Option Phase'!L$4<'Single Project Assumptions'!$D$15),'Single Project Assumptions'!$D$50/12,0) -> 0 | ... DU7: =IF(AND(DU$4>='Single Project Assumptions'!$D$11,'Option Phase'!DU$4<'Single Project Assumptions'!$D$15),'Single Project Assumptions'!$D$50/12,0) -> 0
C8: Option Payment (The Commons) | D8: =SUM(E8:DU8) -> -50000 | E8: =IF(E$4='Single Project Assumptions'!$H$50,-'Single Project Assumptions'!$H$49,0) -> -50000 | F8: =IF(F$4='Single Project Assumptions'!$H$50,-'Single Project Assumptions'!$H$49,0) -> 0 | G8: =IF(G$4='Single Project Assumptions'!$H$50,-'Single Project Assumptions'!$H$49,0) -> 0 | H8: =IF(H$4='Single Project Assumptions'!$H$50,-'Single Project Assumptions'!$H$49,0) -> 0 | I8: =IF(I$4='Single Project Assumptions'!$H$50,-'Single Project Assumptions'!$H$49,0) -> 0 | J8: =IF(J$4='Single Project Assumptions'!$H$50,-'Single Project Assumptions'!$H$49,0) -> 0 | K8: =IF(K$4='Single Project Assumptions'!$H$50,-'Single Project Assumptions'!$H$49,0) -> 0 | L8: =IF(L$4='Single Project Assumptions'!$H$50,-'Single Project Assumptions'!$H$49,0) -> 0 | ... DU8: =IF(DU$4='Single Project Assumptions'!$H$50,-'Single Project Assumptions'!$H$49,0) -> 0
C9: Landowner Net Cash Flow | D9: =SUM(E9:DU9) -> -40000 | E9: =SUM(E7:E8) -> -48333.333 | F9: =SUM(F7:F8) -> 1666.6667 | G9: =SUM(G7:G8) -> 1666.6667 | H9: =SUM(H7:H8) -> 1666.6667 | I9: =SUM(I7:I8) -> 1666.6667 | J9: =SUM(J7:J8) -> 1666.6667 | K9: =SUM(K7:K8) -> 0 | L9: =SUM(L7:L8) -> 0 | ... DU9: =SUM(DU7:DU8) -> 0
C11: The Commons
C12: Option Payment (The Commons) | D12: =SUM(E12:DU12) -> 50000 | E12: =-E8 -> 50000 | F12: =-F8 -> 0 | G12: =-G8 -> 0 | H12: =-H8 -> 0 | I12: =-I8 -> 0 | J12: =-J8 -> 0 | K12: =-K8 -> 0 | L12: =-L8 -> 0 | ... DU12: =-DU8 -> 0
C13: Costs to Secure Entitlement Investor | D13: =SUM(E13:DU13) -> -20000 | E13: =IF(AND(E$4>='Single Project Assumptions'!$H$52,'Option Phase'!E$4<'Single Project Assumptions'!$H$53),-'Single Project Assumptions'!$H$51/'Single Project Assumptions'!$H$54,0) -> -3333.3333 | F13: =IF(AND(F$4>='Single Project Assumptions'!$H$52,'Option Phase'!F$4<'Single Project Assumptions'!$H$53),-'Single Project Assumptions'!$H$51/'Single Project Assumptions'!$H$54,0) -> -3333.3333 | G13: =IF(AND(G$4>='Single Project Assumptions'!$H$52,'Option Phase'!G$4<'Single Project Assumptions'!$H$53),-'Single Project Assumptions'!$H$51/'Single Project Assumptions'!$H$54,0) -> -3333.3333 | H13: =IF(AND(H$4>='Single Project Assumptions'!$H$52,'Option Phase'!H$4<'Single Project Assumptions'!$H$53),-'Single Project Assumptions'!$H$51/'Single Project Assumptions'!$H$54,0) -> -3333.3333 | I13: =IF(AND(I$4>='Single Project Assumptions'!$H$52,'Option Phase'!I$4<'Single Project Assumptions'!$H$53),-'Single Project Assumptions'!$H$51/'Single Project Assumptions'!$H$54,0) -> -3333.3333 | J13: =IF(AND(J$4>='Single Project Assumptions'!$H$52,'Option Phase'!J$4<'Single Project Assumptions'!$H$53),-'Single Project Assumptions'!$H$51/'Single Project Assumptions'!$H$54,0) -> -3333.3333 | K13: =IF(AND(K$4>='Single Project Assumptions'!$H$52,'Option Phase'!K$4<'Single Project Assumptions'!$H$53),-'Single Project Assumptions'!$H$51/'Single Project Assumptions'!$H$54,0) -> 0 | L13: =IF(AND(L$4>='Single Project Assumptions'!$H$52,'Option Phase'!L$4<'Single Project Assumptions'!$H$53),-'Single Project Assumptions'!$H$51/'Single Project Assumptions'!$H$54,0) -> 0 | ... DU13: =IF(AND(DU$4>='Single Project Assumptions'!$H$52,'Option Phase'!DU$4<'Single Project Assumptions'!$H$53),-'Single Project Assumptions'!$H$51/'Single Project Assumptions'!$H$54,0) -> 0
C14: The Commons Net Cash Flow | D14: =SUM(E14:DU14) -> 30000 | E14: =SUM(E12:E13) -> 46666.667 | F14: =SUM(F12:F13) -> -3333.3333 | G14: =SUM(G12:G13) -> -3333.3333 | H14: =SUM(H12:H13) -> -3333.3333 | I14: =SUM(I12:I13) -> -3333.3333 | J14: =SUM(J12:J13) -> -3333.3333 | K14: =SUM(K12:K13) -> 0 | L14: =SUM(L12:L13) -> 0 | ... DU14: =SUM(DU12:DU13) -> 0

Sheet Entitlement Phase
D2: Flag | E2: =IF(E4='Single Project Assumptions'!$H$11,1,0) -> 0 | F2: =IF(F4='Single Project Assumptions'!$H$11,1,0) -> 0 | G2: =IF(G4='Single Project Assumptions'!$H$11,1,0) -> 0 | H2: =IF(H4='Single Project Assumptions'!$H$11,1,0) -> 0 | I2: =IF(I4='Single Project Assumptions'!$H$11,1,0) -> 0 | J2: =IF(J4='Single Project Assumptions'!$H$11,1,0) -> 0 | K2: =IF(K4='Single Project Assumptions'!$H$11,1,0) -> 1 | L2: =IF(L4='Single Project Assumptions'!$H$11,1,0) -> 0 | ... DU2: =IF(DU4='Single Project Assumptions'!$H$11,1,0) -> 0
D3: Year | E3: =YEAR(E4) -> 2026 | F3: =YEAR(F4) -> 2027 | G3: =YEAR(G4) -> 2027 | H3: =YEAR(H4) -> 2027 | I3: =YEAR(I4) -> 2027 | J3: =YEAR(J4) -> 2027 | K3: =YEAR(K4) -> 2027 | L3: =YEAR(L4) -> 2027 | ... DU3: =YEAR(DU4) -> 2036
C4: Entitlement Phase Cash Flow | D4: Total | E4: ='Single Project Assumptions'!D6 -> 46387 | F4: =EOMONTH(E4,1) -> 46418 | G4: =EOMONTH(F4,1) -> 46446 | H4: =EOMONTH(G4,1) -> 46477 | I4: =EOMONTH(H4,1) -> 46507 | J4: =EOMONTH(I4,1) -> 46538 | K4: =EOMONTH(J4,1) -> 46568 | L4: =EOMONTH(K4,1) -> 46599 | M4: =EOMONTH(L4,1) -> 46630 | ... DU4: =EOMONTH(DT4,1) -> 50040
C6: Entitlement Costs | D6: =SUM(E6:DU6) -> -3750000 | E6: =-IF(AND(E$4>='Single Project Assumptions'!$H$11,'Entitlement Phase'!E$4<'Single Project Assumptions'!$H$13),('Single Project Assumptions'!$H$21/'Single Project Assumptions'!$H$12),0) -> 0 | F6: =-IF(AND(F$4>='Single Project Assumptions'!$H$11,'Entitlement Phase'!F$4<'Single Project Assumptions'!$H$13),('Single Project Assumptions'!$H$21/'Single Project Assumptions'!$H$12),0) -> 0 | G6: =-IF(AND(G$4>='Single Project Assumptions'!$H$11,'Entitlement Phase'!G$4<'Single Project Assumptions'!$H$13),('Single Project Assumptions'!$H$21/'Single Project Assumptions'!$H$12),0) -> 0 | H6: =-IF(AND(H$4>='Single Project Assumptions'!$H$11,'Entitlement Phase'!H$4<'Single Project Assumptions'!$H$13),('Single Project Assumptions'!$H$21/'Single Project Assumptions'!$H$12),0) -> 0 | I6: =-IF(AND(I$4>='Single Project Assumptions'!$H$11,'Entitlement Phase'!I$4<'Single Project Assumptions'!$H$13),('Single Project Assumptions'!$H$21/'Single Project Assumptions'!$H$12),0) -> 0 | J6: =-IF(AND(J$4>='Single Project Assumptions'!$H$11,'Entitlement Phase'!J$4<'Single Project Assumptions'!$H$13),('Single Project Assumptions'!$H$21/'Single Project Assumptions'!$H$12),0) -> 0 | K6: =-IF(AND(K$4>='Single Project Assumptions'!$H$11,'Entitlement Phase'!K$4<'Single Project Assumptions'!$H$13),('Single Project Assumptions'!$H$21/'Single Project Assumptions'!$H$12),0) -> -312500 | L6: =-IF(AND(L$4>='Single Project Assumptions'!$H$11,'Entitlement Phase'!L$4<'Single Project Assumptions'!$H$13),('Single Project Assumptions'!$H$21/'Single Project Assumptions'!$H$12),0) -> -312500 | ... DU6: =-IF(AND(DU$4>='Single Project Assumptions'!$H$11,'Entitlement Phase'!DU$4<'Single Project Assumptions'!$H$13),('Single Project Assumptions'!$H$21/'Single Project Assumptions'!$H$12),0) -> 0
C7: Entitlement Fees (The Commons) | D7: =SUM(E7:DU7) -> -75000 | E7: =IF(AND(E$4>='Single Project Assumptions'!$H$59,'Entitlement Phase'!E$4<'Single Project Assumptions'!$H$60),(-'Single Project Assumptions'!$H$58)/'Single Project Assumptions'!$H$12,0) -> 0 | F7: =IF(AND(F$4>='Single Project Assumptions'!$H$59,'Entitlement Phase'!F$4<'Single Project Assumptions'!$H$60),(-'Single Project Assumptions'!$H$58)/'Single Project Assumptions'!$H$12,0) -> 0 | G7: =IF(AND(G$4>='Single Project Assumptions'!$H$59,'Entitlement Phase'!G$4<'Single Project Assumptions'!$H$60),(-'Single Project Assumptions'!$H$58)/'Single Project Assumptions'!$H$12,0) -> 0 | H7: =IF(AND(H$4>='Single Project Assumptions'!$H$59,'Entitlement Phase'!H$4<'Single Project Assumptions'!$H$60),(-'Single Project Assumptions'!$H$58)/'Single Project Assumptions'!$H$12,0) -> 0 | I7: =IF(AND(I$4>='Single Project Assumptions'!$H$59,'Entitlement Phase'!I$4<'Single Project Assumptions'!$H$60),(-'Single Project Assumptions'!$H$58)/'Single Project Assumptions'!$H$12,0) -> 0 | J7: =IF(AND(J$4>='Single Project Assumptions'!$H$59,'Entitlement Phase'!J$4<'Single Project Assumptions'!$H$60),(-'Single Project Assumptions'!$H$58)/'Single Project Assumptions'!$H$12,0) -> 0 | K7: =IF(AND(K$4>='Single Project Assumptions'!$H$59,'Entitlement Phase'!K$4<'Single Project Assumptions'!$H$60),(-'Single Project Assumptions'!$H$58)/'Single Project Assumptions'!$H$12,0) -> -6250 | L7: =IF(AND(L$4>='Single Project Assumptions'!$H$59,'Entitlement Phase'!L$4<'Single Project Assumptions'!$H$60),(-'Single Project Assumptions'!$H$58)/'Single Project Assumptions'!$H$12,0) -> -6250 | ... DU7: =IF(AND(DU$4>='Single Project Assumptions'!$H$59,'Entitlement Phase'!DU$4<'Single Project Assumptions'!$H$60),(-'Single Project Assumptions'!$H$58)/'Single Project Assumptions'!$H$12,0) -> 0
